Workbook

Sheet Base Geral
A1: Ano | B1: Commodities | C1: CAPEX (R$/Ha) | D1: OPEX (R$/Ha) | E1: Preço de venda da tonelada - U$D/t | F1: Receita (interna) - mil U$D | G1: Receita (global) - mil U$D | H1: Demanda (Interna) (1000 t) | I1: Demanda (Global) (1000 t) | J1: MarketShareProdução (%) | K1: MarketShareExportação (%) | L1: Área plantada (mil He) | M1: Produção (mil t) | N1: Produção / HE | P1: 0
A2: 2018/2019 | B2: Milho | C2: 44400 | D2: 3980 | E2: 164.41 | F2: =E2*H2 -> 10933265 | G2: =E2*I2 -> 1.8611196e+08 | H2: 66500 | I2: 1131999 | J2: 8.9148744 | K2: 21.705083 | L2: 17493 | M2: 100043 | N2: =M2/L2 -> 5.7190305 | P2: Fonte USDA | T2: 1000
A3: 2019/2020 | B3: Milho | C3: 47800 | D3: 2698.23 | E3: 170.07 | F3: =E3*H3 -> 11564760 | G3: =E3*I3 -> 1.9311074e+08 | H3: 68000 | I3: 1135478 | J3: 9.0408941 | K3: 20.36111 | L3: 18527 | M3: 102501 | N3: =M3/L3 -> 5.5325201 | P3: Conab (grãos)
A4: 2020/2021 | B4: Milho | C4: 57500 | D4: 2598.5 | E4: 165.47 | F4: =E4*H4 -> 11665635 | G4: =E4*I4 -> 1.9090671e+08 | H4: 70500 | I4: 1153724 | J4: 7.6690294 | K4: 11.395865 | L4: 19867 | M4: 87020 | N4: =M4/L4 -> 4.3801279 | P4: Conab (cana) | T4: Commodity | U4: Attribute | V4: Country | W4: 2018/2019 | X4: 2019/2020 | Y4: 2020/2021 | Z4: 2021/2022 | AA4: 2022/2023 | AB4: 2023/2024 | AC4: 2024/2025 | AD4: 2025/2026 | AE4: Unit Description
A5: 2021/2022 | B5: Milho | C5: 80100 | D5: 3766.91 | E5: 259.55 | F5: =E5*H5 -> 18557825 | G5: =E5*I5 -> 3.0686415e+08 | H5: 71500 | I5: 1182293 | J5: 9.5000983 | K5: 23.339614 | L5: 21581.9 | M5: 113272.3 | N5: =M5/L5 -> 5.248486 | P5: Citrus | T5: Sugar, Centrifugal | U5: Cane Sugar Production | V5: Brazil | W5: 29500 | X5: 30300 | Y5: 42050 | Z5: 35450 | AA5: 38050 | AB5: 45544 | AC5: 43700 | AD5: 44386 | AE5: (1000 MT)
A6: 2022/2023 | B6: Milho | C6: 93900 | D6: 6779.69 | E6: 318.81 | F6: =E6*H6 -> 24867180 | G6: =E6*I6 -> 3.7220685e+08 | H6: 78000 | I6: 1167488 | J6: 11.752414 | K6: 30.043961 | L6: 22267.4 | M6: 131866.1 | N6: =M6/L6 -> 5.9219352 | V6: World | W6: 139579 | X6: 125863 | Y6: 142943 | Z6: 142517 | AA6: 143735 | AB6: 141127 | AC6: 139757 | AD6: 149605 | AE6: (1000 MT)
A7: 2023/2024 | B7: Milho | C7: 99100 | D7: 6020.21 | E7: 252.66 | F7: =E7*H7 -> 21223440 | G7: =E7*I7 -> 3.0980841e+08 | H7: 84000 | I7: 1226187 | J7: 9.6659324 | K7: 19.859437 | L7: 21058.5 | M7: 115723.2 | N7: =M7/L7 -> 5.4953202 | U7: Exports | V7: Brazil | W7: 19600 | X7: 19280 | Y7: 32150 | Z7: 25950 | AA7: 28200 | AB7: 35974 | AC7: 34890 | AD7: 35700 | AE7: (1000 MT) | AK7: {=TRANSPOSE(U7:AD8)} -> Exports | AL7: 0
A8: 2024/2025 | B8: Milho | C8: 104700 | D8: 5858.77 | E8: 190.6 | F8: =E8*H8 -> 17630500 | G8: =E8*I8 -> 2.3813526e+08 | H8: 92500 | I8: 1249398 | J8: 11.044537 | K8: 22.48393 | L8: 21857.5 | M8: 139695.8 | N8: =M8/L8 -> 6.3912067 | V8: World | W8: 58285 | X8: 53524 | Y8: 64033 | Z8: 64664 | AA8: 62008 | AB8: 62937 | AC8: 63388 | AD8: 66001 | AE8: (1000 MT) | AK8: Brazil | AL8: World
A9: 2025/2026 | B9: Milho | C9: 109400 | D9: 6386.35 | E9: 203.2 | F9: =E9*H9 -> 19507200 | G9: =E9*I9 -> 2.6179414e+08 | H9: 96000 | I9: 1288357 | J9: 10.145496 | K9: 20.744186 | L9: 22483.2 | M9: 139572 | N9: =M9/L9 -> 6.2078352 | U9: Human Dom. Consumption | V9: Brazil | W9: 10600 | X9: 10650 | Y9: 10150 | Z9: 9500 | AA9: 9500 | AB9: 9500 | AC9: 9000 | AD9: 9000 | AE9: (1000 MT) | AK9: 19600 | AL9: 58285
A10: 2018/2019 | B10: Trigo | C10: 41500 | D10: 3800 | E10: 209.93 | F10: =E10*H10 -> 2498167 | G10: =E10*I10 -> 1.5351215e+08 | H10: 11900 | I10: 731254 | J10: 0.74367065 | K10: 0.34158548 | L10: 2042.4 | M10: 5427.6 | N10: =M10/L10 -> 2.6574618 | V10: World | W10: 171979 | X10: 171456 | Y10: 171275 | Z10: 174026 | AA10: 176568 | AB10: 177015 | AC10: 175772 | AD10: 178113 | AE10: (1000 MT) | AK10: 19280 | AL10: 53524
A11: 2019/2020 | B11: Trigo | C11: 44200 | D11: 2694.24 | E11: 201.69 | F11: =E11*H11 -> 2400111 | G11: =E11*I11 -> 1.4905738e+08 | H11: 11900 | I11: 739042 | J11: 0.67890764 | K11: 0.21840569 | L11: 2039 | M11: 5154 | N11: =M11/L11 -> 2.5277097 | AK11: 32150 | AL11: 64033
A12: 2020/2021 | B12: Trigo | C12: 53800 | D12: 4182.76 | E12: 231.57 | F12: =E12*H12 -> 2732526 | G12: =E12*I12 -> 1.7982406e+08 | H12: 11800 | I12: 776543 | J12: 0.80684922 | K12: 0.45445389 | L12: 2328 | M12: 6814 | N12: =M12/L12 -> 2.9269759 | AK12: 25950 | AL12: 64664
A13: 2021/2022 | B13: Trigo | C13: 76400 | D13: 6453.08 | E13: 315.24 | F13: =E13*H13 -> 3704070 | G13: =E13*I13 -> 2.4829532e+08 | H13: 11750 | I13: 787639 | J13: 0.98345329 | K13: 1.5069112 | L13: 3029.9 | M13: 9365.9 | N13: =M13/L13 -> 3.0911581 | V13: calcular cana dnv | AK13: 28200 | AL13: 62008
A14: 2022/2023 | B14: Trigo | C14: 89500 | D14: 7630.64 | E14: 429.97 | F14: =E14*H14 -> 5095144.5 | G14: =E14*I14 -> 3.3622751e+08 | H14: 11850 | I14: 781979 | J14: 1.3351466 | K14: 1.2105294 | L14: 3450.5 | M14: 10817.5 | N14: =M14/L14 -> 3.1350529 | AK14: 35974 | AL14: 62937
A15: 2023/2024 | B15: Trigo | C15: 94800 | D15: 6391.84 | E15: 340.43 | F15: =E15*H15 -> 4085160 | G15: =E15*I15 -> 2.7151982e+08 | H15: 12000 | I15: 797579 | J15: 1.0229542 | K15: 1.2653557 | L15: 3068.8 | M15: 8807.3 | N15: =M15/L15 -> 2.8699492 | AK15: 34890 | AL15: 63388
A16: 2024/2025 | B16: Trigo | C16: 99200 | D16: 6010.86 | E16: 268.67 | F16: =E16*H16 -> 3277774 | G16: =E16*I16 -> 2.1506227e+08 | H16: 12200 | I16: 800470 | J16: 0.98695404 | K16: 0.89994203 | L16: 2449 | M16: 7536.1 | N16: =M16/L16 -> 3.0772152 | AC16: (WORLD BANK GROUP) | AK16: 35700 | AL16: 66001
A17: 2025/2026 | B17: Trigo | C17: 103700 | D17: 6145.51 | E17: 243.33 | F17: =E17*H17 -> 3005125.5 | G17: =E17*I17 -> 1.985237e+08 | H17: 12350 | I17: 815862 | J17: 0.93265194 | K17: 0.94644901 | L17: 2220.8 | M17: 6616.2 | N17: =M17/L17 -> 2.9791967 | O17: Café (Saca) | P17: Demanda Total Mundo | Q17: Pct. Arábica Mundo | R17: Demanda Total BR | S17: Pct. Arábica BR | T17: Prod café globalarabica | U17: Demanda Global | V17: Demanda Interna | W17: Exportação Global | X17: Exportação Brasil | Y17: Fator de conversão | AC17: 280
A18: 2018/2019 | B18: Café | C18: 50550 | D18: 13888.54 | E18: 2930 | F18: =E18*H18 -> 1930959.8 | G18: =E18*I18 -> 13765163 | H18: =V18*Y18*0.06 -> 659.03064 | I18: =U18*Y18*0.06 -> 4698.0078 | J18: =O18/T18*100 -> 47.344155 | K18: =X18/W18*100 -> 28.991532 | L18: 1449.802 | M18: =O18*60/1000 -> 2982 | N18: =M18/L18 -> 2.0568326 | O18: 49700 | T18: 104976 | U18: 165385 | V18: 23200 | W18: 142890 | X18: 41426 | Y18: =O18/T18 -> 0.47344155 | AC18: 280
A19: 2019/2020 | B19: Café | C19: 53470 | D19: 15065 | E19: 2880 | F19: =E19*H19 -> 1757643.9 | G19: =E19*I19 -> 12366034 | H19: =V19*Y19*0.06 -> 610.29301 | I19: =U19*Y19*0.06 -> 4293.7619 | J19: =O19/T19*100 -> 44.235671 | K19: =X19/W19*100 -> 29.050811 | L19: 1513.2734 | M19: =O19*60/1000 -> 2520 | N19: =M19/L19 -> 1.6652642 | O19: 42000 | T19: 94946 | U19: 161776 | V19: 22994 | W19: 138571 | X19: 40256 | Y19: =O19/T19 -> 0.44235671 | AC19: 280
A20: 2020/2021 | B20: Café | C20: 61400 | D20: 17411.25 | E20: 3320 | F20: =E20*H20 -> 2323187.4 | G20: =E20*I20 -> 16881272 | H20: =V20*Y20*0.06 -> 699.75523 | I20: =U20*Y20*0.06 -> 5084.7205 | J20: =O20/T20*100 -> 52.345544 | K20: =X20/W20*100 -> 31.639651 | L20: 1433.1715 | M20: =O20*60/1000 -> 2982 | N20: =M20/L20 -> 2.0807 | O20: 49700 | T20: 94946 | U20: 161896 | V20: 22280 | W20: 144360 | X20: 45675 | Y20: =O20/T20 -> 0.52345544 | AC20: 390
A21: 2021/2022 | B21: Café | C21: 81500 | D21: 26354.84 | E21: 4510 | F21: =E21*H21 -> 2526673 | G21: =E21*I21 -> 18908540 | H21: =V21*Y21*0.06 -> 560.23792 | I21: =U21*Y21*0.06 -> 4192.5808 | J21: =O21/T21*100 -> 41.796323 | K21: =X21/W21*100 -> 27.570899 | L21: 1452.5774 | M21: =O21*60/1000 -> 2184 | N21: =M21/L21 -> 1.5035343 | O21: 36400 | P21: 168.754 | R21: 22450 | T21: 87089 | U21: 167183 | V21: 22340 | W21: 143938 | X21: 39685 | Y21: =O21/T21 -> 0.41796323 | AC21: 410
A22: 2022/2023 | B22: Café | C22: 98600 | D22: 31075.92 | E22: 5630 | F22: =E22*H22 -> 3438338.6 | G22: =E22*I22 -> 25845585 | H22: =V22*Y22*0.06 -> 610.71734 | I22: =U22*Y22*0.06 -> 4590.6901 | J22: =O22/T22*100 -> 45.339075 | K22: =X22/W22*100 -> 25.194298 | L22: 1485.966 | M22: =O22*60/1000 -> 2388 | N22: =M22/L22 -> 1.6070354 | O22: 39800 | P22: 163968 | R22: 22160 | T22: 87783 | U22: 168754 | V22: 22450 | W22: 143465 | X22: 36145 | Y22: =O22/T22 -> 0.45339075 | AC22: 520
A23: 2023/2024 | B23: Café | C23: 104500 | D23: 26929.7 | E23: 4540 | F23: =E23*H23 -> 2787264.9 | G23: =E23*I23 -> 20623748 | H23: =V23*Y23*0.06 -> 613.93501 | I23: =U23*Y23*0.06 -> 4542.6758 | J23: =O23/T23*100 -> 46.174414 | K23: =X23/W23*100 -> 31.722229 | L23: 1508.744 | M23: =O23*60/1000 -> 2694 | N23: =M23/L23 -> 1.7855912 | O23: 44900 | P23: 171556 | R23: 21970 | T23: 97240 | U23: 163968 | V23: 22160 | W23: 147373 | X23: 46750 | Y23: =O23/T23 -> 0.46174414 | AC23: 450
A24: 2024/2025 | B24: Café | C24: 108600 | D24: 24258.35 | E24: 5620 | F24: =E24*H24 -> 3253041.3 | G24: =E24*I24 -> 25401855 | H24: =V24*Y24*0.06 -> 578.83297 | I24: =U24*Y24*0.06 -> 4519.903 | J24: =O24/T24*100 -> 43.910861 | K24: =X24/W24*100 -> 30.127985 | L24: 1486.837 | M24: =O24*60/1000 -> 2640 | N24: =M24/L24 -> 1.7755813 | O24: 44000 | P24: 169363 | R24: 22280 | T24: 100203 | U24: 171556 | V24: 21970 | W24: 148533 | X24: 44750 | Y24: =O24/T24 -> 0.43910861 | AC24: 370
A25: 2025/2026 | B25: Café | C25: 112400 | D25: 27082.23 | E25: 8470 | F25: =E25*H25 -> 4504658.4 | G25: =E25*I25 -> 35150084 | H25: =V25*Y25*0.06 -> 531.83688 | I25: =U25*Y25*0.06 -> 4149.9509 | J25: =O25/T25*100 -> 39.784327 | K25: =X25/W25*100 -> 27.149472 | L25: 1548.371 | M25: =O25*60/1000 -> 2280 | N25: =M25/L25 -> 1.4725153 | O25: 38000 | P25: 173852 | R25: 22280 | T25: 95515 | U25: 173852 | V25: 22280 | W25: 150095 | X25: 40750 | Y25: =O25/T25 -> 0.39784327
A26: 2018/2019 | B26: Citros | C26: 53261.46 | D26: 18739.91 | E26: 790 | F26: =E26*H26 -> 15268330 | G26: =E26*I26 -> 23944900 | H26: 19327 | I26: 30310 | J26: 63.368202 | K26: 69.788715 | L26: 601.5 | M26: 11.668 | N26: =M26/L26 -> 0.019398171
A27: 2019/2020 | B27: Citros | C27: 49630.31 | D27: 19842.34 | E27: 560 | F27: =E27*H27 -> 8338960 | G27: =E27*I27 -> 16478000 | H27: 14891 | I27: 29425 | J27: 63.829541 | K27: 72.674317 | L27: 595.8 | M27: 15.781 | N27: =M27/L27 -> 0.026487076
A28: 2020/2021 | B28: Citros | C28: 55314.48 | D28: 20786.68 | E28: 600 | F28: =E28*H28 -> 8820000 | G28: =E28*I28 -> 18069600 | H28: 14700 | I28: 30116 | J28: 60.5455 | K28: 68.972487 | L28: 595.7 | M28: 10.96 | N28: =M28/L28 -> 0.018398523
A29: 2021/2022 | B29: Citros | C29: 52971.88 | D29: 25223.82 | E29: 650 | F29: =E29*H29 -> 11024000 | G29: =E29*I29 -> 20044050 | H29: 16960 | I29: 30837 | J29: 67.224323 | K29: 71.099939 | L29: 604.4 | M29: 10.729 | N29: =M29/L29 -> 0.017751489
A30: 2022/2023 | B30: Citros | C30: 85401.25 | D30: 32173.12 | E30: 920 | F30: =E30*H30 -> 14268280 | G30: =E30*I30 -> 27862200 | H30: 15509 | I30: 30285 | J30: 74.843104 | K30: 73.69416 | L30: 600 | M30: 12.82 | N30: =M30/L30 -> 0.021366667
A31: 2023/2024 | B31: Citros | C31: 98218.85 | D31: 33350.77 | E31: 1570 | F31: =E31*H31 -> 19395780 | G31: =E31*I31 -> 46245920 | H31: 12354 | I31: 29456 | J31: 66.877149 | K31: 68.884462 | L31: 590 | M31: 12.535 | N31: =M31/L31 -> 0.021245763
A32: 2024/2025 | B32: Citros | C32: 96166.67 | D32: 37684.31 | E32: 2260 | F32: =E32*H32 -> 29470400 | G32: =E32*I32 -> 64712840 | H32: 13040 | I32: 28634 | J32: 75.567705 | K32: 77.046103 | L32: 590 | M32: 9.419 | N32: =M32/L32 -> 0.015964407
A33: 2025/2026 | B33: Citros | C33: 111764.79 | D33: 43278.86 | E33: 1420 | F33: =E33*H33 -> 19248100 | G33: =E33*I33 -> 40431660 | H33: 13555 | I33: 28473 | J33: 76.381161 | K33: 76.482579 | L33: 590 | M33: 11.952 | N33: =M33/L33 -> 0.020257627
A34: 2018/2019 | B34: Cana | C34: =N34*O34 -> 940548.08 | D34: 361170.55 | E34: =F34/M34 -> 38.460992 | F34: 23862561 | G34: =F34/J34 -> 78566999 | H34: 618362.43 | I34: =H34/J34 -> 2035945.8 | J34: =(M34*1000)/'Açúcar e Etanol'!O25 -> 0.30372244 | K34: =AK9/AL9 -> 0.33627863 | L34: 8589.23 | M34: 620435.39 | N34: =M34/L34 -> 72.234111 | O34: 13020.83
A35: 2019/2020 | B35: Cana | C35: =N35*O35 -> 1057405.3 | D35: 411119.14 | E35: =F35/M35 -> 37.854909 | F35: 24330023 | G35: =F35/J35 -> 78437079 | H35: 615882.14 | I35: =H35/J35 -> 1985530.2 | J35: =(M35*1000)/'Açúcar e Etanol'!O26 -> 0.31018522 | K35: =AK10/AL10 -> 0.36021224 | L35: 8442.02 | M35: 642717.77 | N35: =M35/L35 -> 76.133173 | O35: 13888.89
A36: 2020/2021 | B36: Cana | C36: =N36*O36 -> 564924.45 | D36: 631874.38 | E36: =F36/M36 -> 36.264489 | F36: 23656266 | G36: =F36/J36 -> 72196329 | H36: 614673.82 | I36: =H36/J36 -> 1875917.1 | J36: =(M36*1000)/'Açúcar e Etanol'!O27 -> 0.32766577 | K36: =AK11/AL11 -> 0.50208486 | L36: 8620.26 | M36: 652325.92 | N36: =M36/L36 -> 75.673578 | O36: 7465.28 | Q36: =S36*60/1000 -> 0
A37: 2021/2022 | B37: Cana | C37: =N37*O37 -> 908255.03 | D37: 510037.28 | E37: =F37/M37 -> 52.444278 | F37: 30690868 | G37: =F37/J37 -> 2.0791715e+08 | H37: 533706.76 | I37: =H37/J37 -> 3615629 | J37: =(M37*1000)/'Açúcar e Etanol'!O28 -> 0.14761104 | K37: =AK12/AL12 -> 0.40130521 | L37: 8317.99 | M37: 585209.09 | N37: =M37/L37 -> 70.354628 | O37: 12909.67 | S37: Fazer regra de 3
A38: 2022/2023 | B38: Cana | C38: =N38*O38 -> 1257941.2 | D38: 787830.7 | E38: =F38/M38 -> 55.350532 | F38: 33771096 | G38: =F38/J38 -> 1.1208839e+08 | H38: 605679.97 | I38: =H38/J38 -> 2010290 | J38: =(M38*1000)/'Açúcar e Etanol'!O29 -> 0.30128985 | K38: =AK13/AL13 -> 0.45478003 | L38: 8288.8669 | M38: 610131.37 | N38: =M38/L38 -> 73.608537 | O38: 17089.61
A39: 2023/2024 | B39: Cana | C39: =N39*O39 -> 1500160.5 | D39: 802371.06 | E39: =F39/M39 -> 56.72092 | F39: 40454162 | G39: =F39/J39 -> 1.203874e+08 | H39: 660290.56 | I39: =H39/J39 -> 1964956.4 | J39: =(M39*1000)/'Açúcar e Etanol'!O30 -> 0.33603319 | K39: =AK14/AL14 -> 0.57158746 | L39: 8333.9285 | M39: 713214.13 | N39: =M39/L39 -> 85.579583 | O39: 17529.42 | S39: Commodity | T39: Attribute | V39: Country | W39: 2018/2019 | X39: 2019/2020 | Y39: 2020/2021 | Z39: 2021/2022 | AA39: 2022/2023 | AB39: 2023/2024 | AC39: 2024/2025 | AD39: 2025/2026 | AE39: Unit Description
A40: 2024/2025 | B40: Cana | C40: =N40*O40 -> 932568.32 | D40: 832156.83 | E40: =F40/M40 -> 52.675257 | F40: 36190992 | G40: =F40/J40 -> 1.0720752e+08 | H40: 612546.25 | I40: =H40/J40 -> 1814527.8 | J40: =(M40*1000)/'Açúcar e Etanol'!O31 -> 0.33757887 | K40: =AK15/AL15 -> 0.55041964 | L40: 8853.8318 | M40: 687058.66 | N40: =M40/L40 -> 77.600148 | O40: 12017.61 | S40: Sugar, Centrifugal | T40: Human Dom. Consumption | V40: Brazil | W40: 10600 | X40: 10650 | Y40: 10150 | Z40: 9500 | AA40: 9500 | AB40: 9500 | AC40: 9000 | AD40: 9000 | AE40: (1000 MT)
...

Sheet Sheet4

Sheet Sheet3

Sheet Market Share
B2: Market Share Produção | H2: Market Share Exportação
B3: Café Arábica | C3: Trigo | D3: Citrus | E3: Milho | F3: Cana-de-açúcar | H3: Café Arábica | I3: Trigo | J3: Citrus | K3: Milho | L3: Cana-de-açúcar
B4: 0.4216 | C4: 0.01 | D4: 0.2857 | E4: 0.1104 | F4: 0.3732 | H4: 0.45 | I4: 0.0146 | J4: 0.75 | K4: 0.21 | L4: 0.66
A5: Players até 30% | H5: Brasil (45%) | I5: Russia (20%) | J5: Brasil | K5: EUA (31%) | L5: Brasil (66%)
H6: Colombia (14,8%) | I6: União Europeia (15%) | J6: México(15%) | K6: Brasil ( 21%) | L6: Tailândia (12%)
H7: Etiópia (9%) | I7: Austrália (13%) | J7: Demais(10%) | K7: Argentina (17%) | L7: India (5%)
H8: Demais (32,2%) | I8: Canadá (13%) | K8: Ucrânia (7%) | L8: Demais (83%)
I9: EUA (11%) | K9: Demais(24%)
E10: Matar | I10: Demais (28%)

Sheet Sheet2

Sheet Açúcar e Etanol
D5: Açúcar (mil t) | E5: ATR médio (Kg/t) | F5: Etanol Anidro (mil l) | G5: Etanol Hidratado (mil l) | H5: Etanol Total (mil l) | I5: %Cana que vira açúcar | J5: %Cana para o resto | K5: Preço do açúcar (U$D/t) | L5: Preço etanol anidro (U$D/l) | M5: Preço Etanol Hidratado (U$D/l) | N5: Preço médio (U$D/l) | O5: Demanda Açúcar (1000 t) | P5: Demanda açúcar exportação (1000 t) | Q5: Demanda Etanol total hidratado (1000 l) | R5: Demanda Etanol total Anidro (1000 l) | S5: Demanda Etanol exportação Hidratado(1000l) | T5: Demanda Etanol exportação Anidro (1000l) | U5: Receita açúcar (mil U$D) | V5: Receita açúcar exportação (mil U$D) | W5: Receita Etanol Hidratado (mil U$D) | X5: Receita Etanol Hidratado exportação (mil U$D) | Y5: Receita Etanol Anidro (mil U$D) | Z5: Receita Etanol Anidro exportação (mil U$D) | AA5: Receita total Receita total Açúcar + Etanol (mil U$D) | AF5: Ministério do desenvolvimento agrário
C6: 2018/2019 | D6: 29038.335 | E6: 138.41927 | F6: =9324469*0.976 -> 9100681.7 | G6: =23027174*0.976 -> 22474522 | H6: =32351643*0.976 -> 31575204 | I6: =(D6*1000/E6)/'Base Geral'!M34 -> 0.33812603 | J6: =1-I6 -> 0.66187397 | K6: 280 | L6: 0.50204 | M6: 0.460217 | N6: =AVERAGE(M6,L6) -> 0.4811285 | O6: 10600 | P6: 19129.6 | Q6: 20232480 | R6: 9857600 | S6: 599264 | T6: 997472 | U6: =O6*K6 -> 2968000 | V6: =P6*K6 -> 5356288 | W6: =Q6*M6 -> 9311331.2 | X6: =S6*M6 -> 275791.48 | Y6: =R6*L6 -> 4948909.5 | Z6: =T6*L6 -> 500770.84 | AA6: =SUM(U6:Z6) -> 23361091 | AD6: Fatores de conversão para toneladas de cana equivalente
C7: 2019/2020 | D7: 29795.7 | E7: 139.28994 | F7: =10116456.5*0.934 -> 9448770.4 | G7: =23885161.25*0.934 -> 22308741 | H7: =34001617.75*0.934 -> 31757511 | I7: =(D7*1000/E7)/'Base Geral'!M35 -> 0.33282316 | J7: =1-I7 -> 0.66717684 | K7: 280 | L7: 0.488965 | M7: 0.443783 | N7: =AVERAGE(M7,L7) -> 0.466374 | O7: 10650 | P7: 18007.52 | Q7: 21056096 | R7: 9624870 | S7: 613638 | T7: 1174038 | U7: =O7*K7 -> 2982000 | V7: =P7*K7 -> 5042105.6 | W7: =Q7*M7 -> 9344337.5 | X7: =S7*M7 -> 272322.11 | Y7: =R7*L7 -> 4706224.6 | Z7: =T7*L7 -> 574063.49 | AA7: =SUM(U7:Z7) -> 22921053 | AD7: Etanol Anidro | AE7: Etanol Hidratado | AF7: Açúcar | AH7: Demanda Açúcar (1000 t) | AI7: Demanda açúcar exportação (1000 t) | AJ7: Demanda Etanol total hidratado (1000 l) | AK7: Demanda Etanol total Anidro (1000 l) | AL7: Demanda Etanol exportação Hidratado(1000l) | AM7: Demanda Etanol exportação Anidro (1000l) | AN7: Demanda total cana - Açúcar + Etanol (1000 t)
C8: 2020/2021 | D8: 41254.298 | E8: 144.08027 | F8: =9321811.984*0.885 -> 8249803.6 | G8: =20424610.9889859*0.885 -> 18075781 | H8: =29746422.9729859*0.885 -> 26325584 | I8: =(D8*1000/E8)/'Base Geral'!M36 -> 0.43893483 | J8: =1-I8 -> 0.56106517 | K8: 280 | L8: 0.4052 | M8: 0.356974 | N8: =AVERAGE(M8,L8) -> 0.381087 | O8: 10150 | P8: 28452.75 | Q8: 17043330 | R8: 8557950 | S8: 1385025 | T8: 1006245 | U8: =O8*K8 -> 2842000 | V8: =P8*K8 -> 7966770 | W8: =Q8*M8 -> 6084025.7 | X8: =S8*M8 -> 494417.91 | Y8: =R8*L8 -> 3467681.3 | Z8: =T8*L8 -> 407730.47 | AA8: =SUM(U8:Z8) -> 21262625 | AC8: 2018/2019 | AD8: =($E$6)*0.5665 -> 78.414515 | AE8: =($E$6)*0.5913 -> 81.847312 | AF8: =$E$6/1049.5 -> 0.13189068 | AH8: =(10600)/($E$6/1049.5) -> 80369.592 | AI8: =19129.6/($E$6/1049.5) -> 145041.33 | AJ8: =20232480/(($E$6)*0.5913) -> 247197.85 | AK8: =9857600/(($E$6)*0.5665) -> 125711.42 | AL8: =599264/(($E$6)*0.5913) -> 7321.7309 | AM8: =997472/(($E$6)*0.5665) -> 12720.502 | AN8: =SUM(AH8:AM8) -> 618362.43
C9: 2021/2022 | D9: 35049.166 | E9: 141.60864 | F9: =10604566.59*0.85 -> 9013881.6 | G9: =16181899.1328566*0.85 -> 13754614 | H9: =26786465.7228566*0.85 -> 22768496 | I9: =(D9*1000/E9)/'Base Geral'!M37 -> 0.42293815 | J9: =1-I9 -> 0.57706185 | K9: 390 | L9: 0.630046 | M9: 0.549556 | N9: =AVERAGE(M9,L9) -> 0.589801 | O9: 9500 | P9: 22057.5 | Q9: 14273200 | R9: 9023600 | S9: 867000 | T9: 523600 | U9: =O9*K9 -> 3705000 | V9: =P9*K9 -> 8602425 | W9: =Q9*M9 -> 7843922.7 | X9: =S9*M9 -> 476465.05 | Y9: =R9*L9 -> 5685283.1 | Z9: =T9*L9 -> 329892.09 | AA9: =SUM(U9:Z9) -> 26642988 | AC9: 2019/2020 | AD9: =($E$7)*0.5665 -> 78.907749 | AE9: =($E$7)*0.5913 -> 82.362139 | AF9: =$E$7/1049.5 -> 0.13272028 | AH9: =10650/($E$7/1049.5) -> 80243.953 | AI9: =18007.52/($E$7/1049.5) -> 135680.24 | AJ9: =21056096/(($E$7)*0.5913) -> 255652.61 | AK9: =9624870/(($E$7)*0.5665) -> 121976.23 | AL9: =613638/(($E$7)*0.5913) -> 7450.4864 | AM9: =1174038/(($E$7)*0.5665) -> 14878.615 | AN9: =SUM(AH9:AM9) -> 615882.14
C10: 2022/2023 | D10: 37036.201 | E10: 133.46128 | F10: =11647168.8145081*0.876 -> 10202920 | G10: =15718719.5817395*0.876 -> 13769598 | H10: =27365888.3962476*0.876 -> 23972518 | I10: =(D10*1000/E10)/'Base Geral'!M38 -> 0.45482864 | J10: =1-I10 -> 0.54517136 | K10: 410 | L10: 0.664883 | M10: 0.576473 | N10: =AVERAGE(M10,L10) -> 0.620678 | O10: 9500 | P10: 24703.2 | Q10: 13603404 | R10: 10179996 | S10: 989880 | T10: 1296480 | U10: =O10*K10 -> 3895000 | V10: =P10*K10 -> 10128312 | W10: =Q10*M10 -> 7841995.1 | X10: =S10*M10 -> 570639.09 | Y10: =R10*L10 -> 6768506.3 | Z10: =T10*L10 -> 862007.51 | AA10: =SUM(U10:Z10) -> 30066460 | AC10: 2020/2021 | AD10: =($E$8)*0.5665 -> 81.621475 | AE10: =($E$8)*0.5913 -> 85.194666 | AF10: =$E$8/1049.5 -> 0.13728468 | AH10: =10150/($E$8/1049.5) -> 73933.959 | AI10: =28452.75/($E$8/1049.5) -> 207253.64 | AJ10: =17043330/(($E$8)*0.5913) -> 200051.61 | AK10: =8557950/(($E$8)*0.5665) -> 104849.24 | AL10: =1385025/(($E$8)*0.5913) -> 16257.18 | AM10: =1006245/(($E$8)*0.5665) -> 12328.189 | AN10: =SUM(AH10:AM10) -> 614673.82
C11: 2023/2024 | D11: 45678.702 | E11: 134.55665 | F11: =12049303.487*0.836 -> 10073218 | G11: =17640240.161*0.836 -> 14747241 | H11: =29689543.648*0.836 -> 24820458 | I11: =(D11*1000/E11)/'Base Geral'!M39 -> 0.47597995 | J11: =1-I11 -> 0.52402005 | K11: 520 | L11: 0.55624 | M11: 0.480629 | N11: =AVERAGE(M11,L11) -> 0.5184345 | O11: 9500 | P11: 30074.264 | Q11: 15217708 | R11: 10200036 | S11: 1187120 | T11: 886160 | U11: =O11*K11 -> 4940000 | V11: =P11*K11 -> 15638617 | W11: =Q11*M11 -> 7314071.8 | X11: =S11*M11 -> 570564.3 | Y11: =R11*L11 -> 5673668 | Z11: =T11*L11 -> 492917.64 | AA11: =SUM(U11:Z11) -> 34629839 | AC11: 2021/2022 | AD11: =($E$9)*0.5665 -> 80.221297 | AE11: =($E$9)*0.5913 -> 83.733192 | AF11: =$E$9/1049.5 -> 0.13492963 | AH11: =9500/($E$9/1049.5) -> 70407.072 | AI11: =22057.5/($E$9/1049.5) -> 163474.1 | AJ11: =14273200/(($E$9)*0.5913) -> 170460.48 | AK11: =9023600/(($E$9)*0.5665) -> 112483.85 | AL11: =867000/(($E$9)*0.5913) -> 10354.317 | AM11: =523600/(($E$9)*0.5665) -> 6526.9451 | AN11: =SUM(AH11:AM11) -> 533706.76
C12: 2024/2025 | D12: 44853.387 | E12: 137.26775 | F12: =10467182.5162166*0.766 -> 8017861.8 | G12: =18868830.5433886*0.766 -> 14453524 | H12: =29336013.0596052*0.766 -> 22471386 | I12: =(D12*1000/E12)/'Base Geral'!M40 -> 0.47559023 | J12: =1-I12 -> 0.52440977 | K12: 450 | L12: 0.501319 | M12: 0.443775 | N12: =AVERAGE(M12,L12) -> 0.472547 | O12: 9000 | P12: 26725.74 | Q12: 16595390 | R12: 9257110 | S12: 865580 | T12: 406746 | U12: =O12*K12 -> 4050000 | V12: =P12*K12 -> 12026583 | W12: =Q12*M12 -> 7364619.2 | X12: =S12*M12 -> 384122.76 | Y12: =R12*L12 -> 4640765.1 | Z12: =T12*L12 -> 203909.5 | AA12: =SUM(U12:Z12) -> 28670000 | AC12: 2022/2023 | AD12: =($E$10)*0.5665 -> 75.605813 | AE12: =($E$10)*0.5913 -> 78.915653 | AF12: =$E$10/1049.5 -> 0.12716653 | AH12: =9500/($E$10/1049.5) -> 74705.19 | AI12: =24703.2/($E$10/1049.5) -> 194258.66 | AJ12: =13603404/(($E$10)*0.5913) -> 172379.03 | AK12: =10179996/(($E$10)*0.5665) -> 134645.68 | AL12: =989880/(($E$10)*0.5913) -> 12543.519 | AM12: =1296480/(($E$10)*0.5665) -> 17147.888 | AN12: =SUM(AH12:AM12) -> 605679.97
C13: 2025/2026 | D13: 44179.08 | E13: 134.94994 | F13: =10119720.2009655*0.729 -> 7377276 | G13: =17211219.2582669*0.729 -> 12546979 | H13: =27330939.4592324*0.729 -> 19924255 | I13: =(D13*1000/E13)/'Base Geral'!M41 -> 0.48623451 | J13: =1-I13 -> 0.51376549 | K13: 370 | L13: 0.561408 | M13: 0.489898 | N13: =AVERAGE(M13,L13) -> 0.525653 | O13: 9000 | P13: 26025.3 | Q13: 15204753 | R13: 9962514 | S13: 707130 | T13: 255879 | U13: =O13*K13 -> 3330000 | V13: =P13*K13 -> 9629361 | W13: =Q13*M13 -> 7448778.1 | X13: =S13*M13 -> 346421.57 | Y13: =R13*L13 -> 5593035.1 | Z13: =T13*L13 -> 143652.52 | AA13: =SUM(U13:Z13) -> 26491248 | AC13: 2023/2024 | AD13: =($E$11)*0.5665 -> 76.226341 | AE13: =($E$11)*0.5913 -> 79.563346 | AF13: =$E$11/1049.5 -> 0.12821024 | AH13: =9500/($E$11/1049.5) -> 74097.045 | AI13: =30074.264/($E$11/1049.5) -> 234569.9 | AJ13: =15217708/(($E$11)*0.5913) -> 191265.31 | AK13: =10200036/(($E$11)*0.5665) -> 133812.48 | AL13: =1187120/(($E$11)*0.5913) -> 14920.438 | AM13: =886160/(($E$11)*0.5665) -> 11625.378 | AN13: =SUM(AH13:AM13) -> 660290.56
AC14: 2024/2025 | AD14: =($E$12)*0.5665 -> 77.762179 | AE14: =($E$12)*0.5913 -> 81.166419 | AF14: =$E$12/1049.5 -> 0.13079347 | AH14: =9000/($E$12/1049.5) -> 68810.774 | AI14: =26725.74/($E$12/1049.5) -> 204335.43 | AJ14: =16595390/(($E$12)*0.5913) -> 204461.28 | AK14: =9257110/(($E$12)*0.5665) -> 119043.86 | AL14: =865580/(($E$12)*0.5913) -> 10664.262 | AM14: =406746/(($E$12)*0.5665) -> 5230.6404 | AN14: =SUM(AH14:AM14) -> 612546.25
AC15: 2025/2026 | AD15: =($E$13)*0.5665 -> 76.44914 | AE15: =($E$13)*0.5913 -> 79.795898 | AF15: =$E$13/1049.5 -> 0.12858498 | AH15: =9000/($E$13/1049.5) -> 69992.622 | AI15: =26025.3/($E$13/1049.5) -> 202397.66 | AJ15: =15204753/(($E$13)*0.5913) -> 190545.55 | AK15: =9962514/(($E$13)*0.5665) -> 130315.58 | AL15: =707130/(($E$13)*0.5913) -> 8861.7337 | AM15: =255879/(($E$13)*0.5665) -> 3347.0488 | AN15: =SUM(AH15:AM15) -> 605460.19
G16: 0.976 | L16: cepea | O16: USDA
G17: 0.934 | J17: Os demais Subprodutos são desprezíveis frente o Etanol | L17: **Preço médio anual com base nos relatórios semanais
G18: 0.885
G19: 0.85 | T19: Safra | U19: Etanol anidro exportado | V19: Etanol hidratado exportado | W19: Total exportado | X19: Qualidade do dado
G20: 0.876 | T20: 2018/19 | U20: 1022 | V20: 614 | W20: 1635 | X20: UNICA / Centro-Sul
G21: 0.836 | T21: 2019/20 | U21: 1257 | V21: 657 | W21: 1914 | X21: UNICA / Centro-Sul
G22: 0.766 | T22: 2020/21E | U22: 1137 | V22: 1565 | W22: 2700 | X22: Estimado por variação contra 2021/22
G23: 0.729 | T23: 2021/22 | U23: 616 | V23: 1020 | W23: 1630 | X23: UNICA / Centro-Sul
O24: Produção global cana de açucar em toneladas | P24: Market Share do Brazil no açúcar | Q24: Demanda Açúcar global (1000 t) | T24: 2022/23 | U24: 1480 | V24: 1130 | W24: 2610 | X24: UNICA / Centro-Sul | AA24: Safra | AB24: Consumo interno anidro (1000 L) | AC24: Consumo interno hidratado (1000 L) | AD24: Consumo interno total (1000 L)
O25: 2.042771e+09 | P25: =('Base Geral'!M34*1000)/'Açúcar e Etanol'!O25 -> 0.30372244 | Q25: 171979 | T25: 2023/24 | U25: 1060 | V25: 1420 | W25: 2480 | X25: UNICA / Centro-Sul | AA25: 2018/19 | AB25: 10100000 | AC25: 20730000 | AD25: 30830000
O26: 2.0720451e+09 | P26: =('Base Geral'!M35*1000)/'Açúcar e Etanol'!O26 -> 0.31018522 | Q26: 171456 | T26: 2024/25 | U26: 531 | V26: 1130 | W26: 1670 | X26: UNICA / Centro-Sul | AA26: 2019/20 | AB26: 10305000 | AC26: 22544000 | AD26: 32849000
O27: 1.9908272e+09 | P27: =('Base Geral'!M36*1000)/'Açúcar e Etanol'!O27 -> 0.32766577 | Q27: 171275 | T27: 2025/26E | U27: 351 | V27: 970 | W27: 1322 | X27: Estimado via Comex Stat / NCM | AA27: 2020/21 | AB27: 9670000 | AC27: 19258000 | AD27: 28928000
O28: 3.9645346e+09 | P28: =('Base Geral'!M37*1000)/'Açúcar e Etanol'!O28 -> 0.14761104 | Q28: 174026 | AA28: 2021/22 | AB28: 10616000 | AC28: 16792000 | AD28: 27408000
O29: 2.0250644e+09 | P29: =('Base Geral'!M38*1000)/'Açúcar e Etanol'!O29 -> 0.30128985 | Q29: 176568 | AA29: 2022/23 | AB29: 11621000 | AC29: 15529000 | AD29: 27150000
O30: 2122451453 | P30: =('Base Geral'!M39*1000)/'Açúcar e Etanol'!O30 -> 0.33603319 | Q30: 177015 | AA30: 2023/24 | AB30: 12201000 | AC30: 18203000 | AD30: 30404000
O31: 2.0352538e+09 | P31: =('Base Geral'!M40*1000)/'Açúcar e Etanol'!O31 -> 0.33757887 | Q31: 175772 | AA31: 2024/25 | AB31: 12085000 | AC31: 21665000 | AD31: 33750000
AA32: 2025/26E | AB32: 13666000 | AC32: 20857000 | AD32: 34523000
